Workbook
Name StartMonth: Inputs!$B$5
Name InitInvest: Inputs!$B$6
Name LotValue0: Inputs!$B$7
Name LotGrowth: Inputs!$B$8
Name NYears: Inputs!$B$9
Name RateA: Inputs!$B$13
Name RateB: Inputs!$B$14
Name RateC: Inputs!$B$15
Name RateD: Inputs!$B$16
Name WdrPct: Inputs!$B$19
Name WdrCap: Inputs!$B$20
Name WdrBase: Inputs!$B$21
Name TaxFreq: Inputs!$B$25
Name TaxLower: Inputs!$B$28:$B$32
Name TaxRate: Inputs!$D$28:$D$32

Sheet Inputs
A1: Straddle Income — Investment Growth Analysis
A2: Yellow cells are inputs. Everything else is a live formula — change any input and the whole workbook recomputes.
A4: 1 · CAPITAL & TIME
A5: Starting month | B5: 46266 | C5: First month of deployment (Mon-YYYY)
A6: Initial investment (INR) | B6: 500000 | C6: Corpus at the starting month
A7: Value of 1 lot at start (INR) | B7: 83333 | C7: ₹5,00,000 / 6 lots ≈ ₹83,333
A8: Lot value increase — year on year | B8: 0.05 | C8: Margin per lot rises as NIFTY/premium grow
A9: Number of years to model | B9: 10 | C9: 1 to 30
C10: → Starting lots (derived): | E10: =INT(Inputs!$B$6/Inputs!$B$7)
A12: 2 · MONTHLY RETURN SCENARIOS — enter returns NET of brokerage, STT and slippage
A13: Scenario A — monthly return | B13: 0.05
A14: Scenario B — monthly return | B14: 0.08
A15: Scenario C — monthly return | B15: 0.1
A16: Scenario D — monthly return (your own) | B16: 0.0425 | C16: 2-decimal precision, e.g. 4.25%
A17: Earned on DEPLOYED capital only (lots × lot value); idle cash earns nothing. These % are assumed ALREADY NET of transaction costs — the only further deductions are govt tax and withdrawals.
A18: 3 · ANNUAL WITHDRAWAL
A19: Withdrawal — % of that year's profit | B19: 0.1
A20: Withdrawal — absolute cap (INR) | B20: 10000000 | C20: ₹1 crore
A21: Withdrawal calculated on | B21: Post-tax profit | C21: Whichever is LOWER of the % and the cap is withdrawn
A22: Withdrawn each year = MIN( % × profit , cap )
A24: 4 · GOVERNMENT TAX (New Regime — 30% base slab already included)
A25: Tax deducted | B25: Quarterly | C25: Quarterly = advance tax leaves the corpus 4×/yr, so it compounds less
A27: Income range | B27: Lower bound (INR) | C27: Surcharge | D27: Effective rate — NEW ← USED | E27: Effective rate — OLD (reference only)
A28: Up to ₹50 Lakh | B28: 0 | C28: 0 | D28: 0.312 | E28: 0.312
A29: ₹50 Lakh – ₹1 Crore | B29: 5000000 | C29: 0.1 | D29: 0.3432 | E29: 0.3432
A30: ₹1 Crore – ₹2 Crore | B30: 10000000 | C30: 0.15 | D30: 0.3588 | E30: 0.3588
A31: ₹2 Crore – ₹5 Crore | B31: 20000000 | C31: 0.25 | D31: 0.39 | E31: 0.39
A32: Above ₹5 Crore | B32: 50000000 | C32: 0.25 | D32: 0.39 | E32: 0.42744
A34: Slab is chosen from ANNUALISED profit, so a growing book climbs into higher surcharge bands over time. Only the NEW-regime column drives the maths.

Sheet Summary
A1: Annual Summary — one row per year, per scenario
A2: =TEXT(StartMonth,"mmm-yyyy")&" to "&TEXT(EDATE(StartMonth,NYears*12-1),"mmm-yyyy")&" · "&TEXT(NYears,"0")&" years · initial "&TEXT(InitInvest,"₹##\,##\,##0")&" = "&TEXT(INT(InitInvest/LotValue0),"0")&" lots"
A4: HEADLINE — where each scenario ends up
A5: Scenario | B5: Monthly return | C5: Final corpus | D5: Final lots | E5: Lots growth × | F5: Total tax paid | G5: Total withdrawn | H5: Corpus ×
A6: Scenario A | B6: =RateA | C6: =INDEX($M$14:$M$43,NYears) | D6: =INDEX($F$14:$F$43,NYears) | E6: =INDEX($F$14:$F$43,NYears)/INT(InitInvest/LotValue0) | F6: =SUM($J$14:$J$43) | G6: =SUM($K$14:$K$43) | H6: =(INDEX($M$14:$M$43,NYears)+SUM($K$14:$K$43))/InitInvest
A7: Scenario B | B7: =RateB | C7: =INDEX($M$47:$M$76,NYears) | D7: =INDEX($F$47:$F$76,NYears) | E7: =INDEX($F$47:$F$76,NYears)/INT(InitInvest/LotValue0) | F7: =SUM($J$47:$J$76) | G7: =SUM($K$47:$K$76) | H7: =(INDEX($M$47:$M$76,NYears)+SUM($K$47:$K$76))/InitInvest
A8: Scenario C | B8: =RateC | C8: =INDEX($M$80:$M$109,NYears) | D8: =INDEX($F$80:$F$109,NYears) | E8: =INDEX($F$80:$F$109,NYears)/INT(InitInvest/LotValue0) | F8: =SUM($J$80:$J$109) | G8: =SUM($K$80:$K$109) | H8: =(INDEX($M$80:$M$109,NYears)+SUM($K$80:$K$109))/InitInvest
A9: Scenario D | B9: =RateD | C9: =INDEX($M$113:$M$142,NYears) | D9: =INDEX($F$113:$F$142,NYears) | E9: =INDEX($F$113:$F$142,NYears)/INT(InitInvest/LotValue0) | F9: =SUM($J$113:$J$142) | G9: =SUM($K$113:$K$142) | H9: =(INDEX($M$113:$M$142,NYears)+SUM($K$113:$K$142))/InitInvest
A10: "Corpus ×" counts money taken out as well as money still invested — otherwise a big withdrawal looks like worse performance. Lots growth is the honest measure of deployed scale.
A12: SCENARIO A | B12: =RateA | C12: per month
A13: Year | B13: Year ending | C13: Lot value | D13: Opening corpus | E13: Lots start | F13: Lots end | G13: Lots added | H13: Deployed capital | I13: TRADING PROFIT (net of charges, pre-tax) | J13: Govt tax | K13: Withdrawal | L13: REAL PROFIT (post tax & withdrawal) | M13: Closing corpus
A14: =1 | B14: =IF($A14>NYears,"",EDATE(StartMonth,$A14*12-1)) | C14: =IF($A14>NYears,"",'Engine A'!$E16) | D14: =IF($A14>NYears,"",'Engine A'!$F5) | E14: =IF($A14>NYears,"",'Engine A'!$G5) | F14: =IF($A14>NYears,"",'Engine A'!$S16) | G14: =IF($A14>NYears,"",'Engine A'!$S16-'Engine A'!$G5) | H14: =IF($A14>NYears,"",'Engine A'!$S16*'Engine A'!$E16) | I14: =IF($A14>NYears,"",'Engine A'!$K16) | J14: =IF($A14>NYears,"",'Engine A'!$P16) | K14: =IF($A14>NYears,"",'Engine A'!$Q16) | L14: =IF($A14>NYears,"",'Engine A'!$K16-'Engine A'!$P16-'Engine A'!$Q16) | M14: =IF($A14>NYears,"",'Engine A'!$R16)
A15: =2 | B15: =IF($A15>NYears,"",EDATE(StartMonth,$A15*12-1)) | C15: =IF($A15>NYears,"",'Engine A'!$E28) | D15: =IF($A15>NYears,"",'Engine A'!$F17) | E15: =IF($A15>NYears,"",'Engine A'!$G17) | F15: =IF($A15>NYears,"",'Engine A'!$S28) | G15: =IF($A15>NYears,"",'Engine A'!$S28-'Engine A'!$G17) | H15: =IF($A15>NYears,"",'Engine A'!$S28*'Engine A'!$E28) | I15: =IF($A15>NYears,"",'Engine A'!$K28) | J15: =IF($A15>NYears,"",'Engine A'!$P28) | K15: =IF($A15>NYears,"",'Engine A'!$Q28) | L15: =IF($A15>NYears,"",'Engine A'!$K28-'Engine A'!$P28-'Engine A'!$Q28) | M15: =IF($A15>NYears,"",'Engine A'!$R28)
A16: =3 | B16: =IF($A16>NYears,"",EDATE(StartMonth,$A16*12-1)) | C16: =IF($A16>NYears,"",'Engine A'!$E40) | D16: =IF($A16>NYears,"",'Engine A'!$F29) | E16: =IF($A16>NYears,"",'Engine A'!$G29) | F16: =IF($A16>NYears,"",'Engine A'!$S40) | G16: =IF($A16>NYears,"",'Engine A'!$S40-'Engine A'!$G29) | H16: =IF($A16>NYears,"",'Engine A'!$S40*'Engine A'!$E40) | I16: =IF($A16>NYears,"",'Engine A'!$K40) | J16: =IF($A16>NYears,"",'Engine A'!$P40) | K16: =IF($A16>NYears,"",'Engine A'!$Q40) | L16: =IF($A16>NYears,"",'Engine A'!$K40-'Engine A'!$P40-'Engine A'!$Q40) | M16: =IF($A16>NYears,"",'Engine A'!$R40)
A17: =4 | B17: =IF($A17>NYears,"",EDATE(StartMonth,$A17*12-1)) | C17: =IF($A17>NYears,"",'Engine A'!$E52) | D17: =IF($A17>NYears,"",'Engine A'!$F41) | E17: =IF($A17>NYears,"",'Engine A'!$G41) | F17: =IF($A17>NYears,"",'Engine A'!$S52) | G17: =IF($A17>NYears,"",'Engine A'!$S52-'Engine A'!$G41) | H17: =IF($A17>NYears,"",'Engine A'!$S52*'Engine A'!$E52) | I17: =IF($A17>NYears,"",'Engine A'!$K52) | J17: =IF($A17>NYears,"",'Engine A'!$P52) | K17: =IF($A17>NYears,"",'Engine A'!$Q52) | L17: =IF($A17>NYears,"",'Engine A'!$K52-'Engine A'!$P52-'Engine A'!$Q52) | M17: =IF($A17>NYears,"",'Engine A'!$R52)
A18: =5 | B18: =IF($A18>NYears,"",EDATE(StartMonth,$A18*12-1)) | C18: =IF($A18>NYears,"",'Engine A'!$E64) | D18: =IF($A18>NYears,"",'Engine A'!$F53) | E18: =IF($A18>NYears,"",'Engine A'!$G53) | F18: =IF($A18>NYears,"",'Engine A'!$S64) | G18: =IF($A18>NYears,"",'Engine A'!$S64-'Engine A'!$G53) | H18: =IF($A18>NYears,"",'Engine A'!$S64*'Engine A'!$E64) | I18: =IF($A18>NYears,"",'Engine A'!$K64) | J18: =IF($A18>NYears,"",'Engine A'!$P64) | K18: =IF($A18>NYears,"",'Engine A'!$Q64) | L18: =IF($A18>NYears,"",'Engine A'!$K64-'Engine A'!$P64-'Engine A'!$Q64) | M18: =IF($A18>NYears,"",'Engine A'!$R64)
A19: =6 | B19: =IF($A19>NYears,"",EDATE(StartMonth,$A19*12-1)) | C19: =IF($A19>NYears,"",'Engine A'!$E76) | D19: =IF($A19>NYears,"",'Engine A'!$F65) | E19: =IF($A19>NYears,"",'Engine A'!$G65) | F19: =IF($A19>NYears,"",'Engine A'!$S76) | G19: =IF($A19>NYears,"",'Engine A'!$S76-'Engine A'!$G65) | H19: =IF($A19>NYears,"",'Engine A'!$S76*'Engine A'!$E76) | I19: =IF($A19>NYears,"",'Engine A'!$K76) | J19: =IF($A19>NYears,"",'Engine A'!$P76) | K19: =IF($A19>NYears,"",'Engine A'!$Q76) | L19: =IF($A19>NYears,"",'Engine A'!$K76-'Engine A'!$P76-'Engine A'!$Q76) | M19: =IF($A19>NYears,"",'Engine A'!$R76)
A20: =7 | B20: =IF($A20>NYears,"",EDATE(StartMonth,$A20*12-1)) | C20: =IF($A20>NYears,"",'Engine A'!$E88) | D20: =IF($A20>NYears,"",'Engine A'!$F77) | E20: =IF($A20>NYears,"",'Engine A'!$G77) | F20: =IF($A20>NYears,"",'Engine A'!$S88) | G20: =IF($A20>NYears,"",'Engine A'!$S88-'Engine A'!$G77) | H20: =IF($A20>NYears,"",'Engine A'!$S88*'Engine A'!$E88) | I20: =IF($A20>NYears,"",'Engine A'!$K88) | J20: =IF($A20>NYears,"",'Engine A'!$P88) | K20: =IF($A20>NYears,"",'Engine A'!$Q88) | L20: =IF($A20>NYears,"",'Engine A'!$K88-'Engine A'!$P88-'Engine A'!$Q88) | M20: =IF($A20>NYears,"",'Engine A'!$R88)
A21: =8 | B21: =IF($A21>NYears,"",EDATE(StartMonth,$A21*12-1)) | C21: =IF($A21>NYears,"",'Engine A'!$E100) | D21: =IF($A21>NYears,"",'Engine A'!$F89) | E21: =IF($A21>NYears,"",'Engine A'!$G89) | F21: =IF($A21>NYears,"",'Engine A'!$S100) | G21: =IF($A21>NYears,"",'Engine A'!$S100-'Engine A'!$G89) | H21: =IF($A21>NYears,"",'Engine A'!$S100*'Engine A'!$E100) | I21: =IF($A21>NYears,"",'Engine A'!$K100) | J21: =IF($A21>NYears,"",'Engine A'!$P100) | K21: =IF($A21>NYears,"",'Engine A'!$Q100) | L21: =IF($A21>NYears,"",'Engine A'!$K100-'Engine A'!$P100-'Engine A'!$Q100) | M21: =IF($A21>NYears,"",'Engine A'!$R100)
A22: =9 | B22: =IF($A22>NYears,"",EDATE(StartMonth,$A22*12-1)) | C22: =IF($A22>NYears,"",'Engine A'!$E112) | D22: =IF($A22>NYears,"",'Engine A'!$F101) | E22: =IF($A22>NYears,"",'Engine A'!$G101) | F22: =IF($A22>NYears,"",'Engine A'!$S112) | G22: =IF($A22>NYears,"",'Engine A'!$S112-'Engine A'!$G101) | H22: =IF($A22>NYears,"",'Engine A'!$S112*'Engine A'!$E112) | I22: =IF($A22>NYears,"",'Engine A'!$K112) | J22: =IF($A22>NYears,"",'Engine A'!$P112) | K22: =IF($A22>NYears,"",'Engine A'!$Q112) | L22: =IF($A22>NYears,"",'Engine A'!$K112-'Engine A'!$P112-'Engine A'!$Q112) | M22: =IF($A22>NYears,"",'Engine A'!$R112)
A23: =10 | B23: =IF($A23>NYears,"",EDATE(StartMonth,$A23*12-1)) | C23: =IF($A23>NYears,"",'Engine A'!$E124) | D23: =IF($A23>NYears,"",'Engine A'!$F113) | E23: =IF($A23>NYears,"",'Engine A'!$G113) | F23: =IF($A23>NYears,"",'Engine A'!$S124) | G23: =IF($A23>NYears,"",'Engine A'!$S124-'Engine A'!$G113) | H23: =IF($A23>NYears,"",'Engine A'!$S124*'Engine A'!$E124) | I23: =IF($A23>NYears,"",'Engine A'!$K124) | J23: =IF($A23>NYears,"",'Engine A'!$P124) | K23: =IF($A23>NYears,"",'Engine A'!$Q124) | L23: =IF($A23>NYears,"",'Engine A'!$K124-'Engine A'!$P124-'Engine A'!$Q124) | M23: =IF($A23>NYears,"",'Engine A'!$R124)
A24: =11 | B24: =IF($A24>NYears,"",EDATE(StartMonth,$A24*12-1)) | C24: =IF($A24>NYears,"",'Engine A'!$E136) | D24: =IF($A24>NYears,"",'Engine A'!$F125) | E24: =IF($A24>NYears,"",'Engine A'!$G125) | F24: =IF($A24>NYears,"",'Engine A'!$S136) | G24: =IF($A24>NYears,"",'Engine A'!$S136-'Engine A'!$G125) | H24: =IF($A24>NYears,"",'Engine A'!$S136*'Engine A'!$E136) | I24: =IF($A24>NYears,"",'Engine A'!$K136) | J24: =IF($A24>NYears,"",'Engine A'!$P136) | K24: =IF($A24>NYears,"",'Engine A'!$Q136) | L24: =IF($A24>NYears,"",'Engine A'!$K136-'Engine A'!$P136-'Engine A'!$Q136) | M24: =IF($A24>NYears,"",'Engine A'!$R136)
A25: =12 | B25: =IF($A25>NYears,"",EDATE(StartMonth,$A25*12-1)) | C25: =IF($A25>NYears,"",'Engine A'!$E148) | D25: =IF($A25>NYears,"",'Engine A'!$F137) | E25: =IF($A25>NYears,"",'Engine A'!$G137) | F25: =IF($A25>NYears,"",'Engine A'!$S148) | G25: =IF($A25>NYears,"",'Engine A'!$S148-'Engine A'!$G137) | H25: =IF($A25>NYears,"",'Engine A'!$S148*'Engine A'!$E148) | I25: =IF($A25>NYears,"",'Engine A'!$K148) | J25: =IF($A25>NYears,"",'Engine A'!$P148) | K25: =IF($A25>NYears,"",'Engine A'!$Q148) | L25: =IF($A25>NYears,"",'Engine A'!$K148-'Engine A'!$P148-'Engine A'!$Q148) | M25: =IF($A25>NYears,"",'Engine A'!$R148)
A26: =13 | B26: =IF($A26>NYears,"",EDATE(StartMonth,$A26*12-1)) | C26: =IF($A26>NYears,"",'Engine A'!$E160) | D26: =IF($A26>NYears,"",'Engine A'!$F149) | E26: =IF($A26>NYears,"",'Engine A'!$G149) | F26: =IF($A26>NYears,"",'Engine A'!$S160) | G26: =IF($A26>NYears,"",'Engine A'!$S160-'Engine A'!$G149) | H26: =IF($A26>NYears,"",'Engine A'!$S160*'Engine A'!$E160) | I26: =IF($A26>NYears,"",'Engine A'!$K160) | J26: =IF($A26>NYears,"",'Engine A'!$P160) | K26: =IF($A26>NYears,"",'Engine A'!$Q160) | L26: =IF($A26>NYears,"",'Engine A'!$K160-'Engine A'!$P160-'Engine A'!$Q160) | M26: =IF($A26>NYears,"",'Engine A'!$R160)
A27: =14 | B27: =IF($A27>NYears,"",EDATE(StartMonth,$A27*12-1)) | C27: =IF($A27>NYears,"",'Engine A'!$E172) | D27: =IF($A27>NYears,"",'Engine A'!$F161) | E27: =IF($A27>NYears,"",'Engine A'!$G161) | F27: =IF($A27>NYears,"",'Engine A'!$S172) | G27: =IF($A27>NYears,"",'Engine A'!$S172-'Engine A'!$G161) | H27: =IF($A27>NYears,"",'Engine A'!$S172*'Engine A'!$E172) | I27: =IF($A27>NYears,"",'Engine A'!$K172) | J27: =IF($A27>NYears,"",'Engine A'!$P172) | K27: =IF($A27>NYears,"",'Engine A'!$Q172) | L27: =IF($A27>NYears,"",'Engine A'!$K172-'Engine A'!$P172-'Engine A'!$Q172) | M27: =IF($A27>NYears,"",'Engine A'!$R172)
A28: =15 | B28: =IF($A28>NYears,"",EDATE(StartMonth,$A28*12-1)) | C28: =IF($A28>NYears,"",'Engine A'!$E184) | D28: =IF($A28>NYears,"",'Engine A'!$F173) | E28: =IF($A28>NYears,"",'Engine A'!$G173) | F28: =IF($A28>NYears,"",'Engine A'!$S184) | G28: =IF($A28>NYears,"",'Engine A'!$S184-'Engine A'!$G173) | H28: =IF($A28>NYears,"",'Engine A'!$S184*'Engine A'!$E184) | I28: =IF($A28>NYears,"",'Engine A'!$K184) | J28: =IF($A28>NYears,"",'Engine A'!$P184) | K28: =IF($A28>NYears,"",'Engine A'!$Q184) | L28: =IF($A28>NYears,"",'Engine A'!$K184-'Engine A'!$P184-'Engine A'!$Q184) | M28: =IF($A28>NYears,"",'Engine A'!$R184)
A29: =16 | B29: =IF($A29>NYears,"",EDATE(StartMonth,$A29*12-1)) | C29: =IF($A29>NYears,"",'Engine A'!$E196) | D29: =IF($A29>NYears,"",'Engine A'!$F185) | E29: =IF($A29>NYears,"",'Engine A'!$G185) | F29: =IF($A29>NYears,"",'Engine A'!$S196) | G29: =IF($A29>NYears,"",'Engine A'!$S196-'Engine A'!$G185) | H29: =IF($A29>NYears,"",'Engine A'!$S196*'Engine A'!$E196) | I29: =IF($A29>NYears,"",'Engine A'!$K196) | J29: =IF($A29>NYears,"",'Engine A'!$P196) | K29: =IF($A29>NYears,"",'Engine A'!$Q196) | L29: =IF($A29>NYears,"",'Engine A'!$K196-'Engine A'!$P196-'Engine A'!$Q196) | M29: =IF($A29>NYears,"",'Engine A'!$R196)
A30: =17 | B30: =IF($A30>NYears,"",EDATE(StartMonth,$A30*12-1)) | C30: =IF($A30>NYears,"",'Engine A'!$E208) | D30: =IF($A30>NYears,"",'Engine A'!$F197) | E30: =IF($A30>NYears,"",'Engine A'!$G197) | F30: =IF($A30>NYears,"",'Engine A'!$S208) | G30: =IF($A30>NYears,"",'Engine A'!$S208-'Engine A'!$G197) | H30: =IF($A30>NYears,"",'Engine A'!$S208*'Engine A'!$E208) | I30: =IF($A30>NYears,"",'Engine A'!$K208) | J30: =IF($A30>NYears,"",'Engine A'!$P208) | K30: =IF($A30>NYears,"",'Engine A'!$Q208) | L30: =IF($A30>NYears,"",'Engine A'!$K208-'Engine A'!$P208-'Engine A'!$Q208) | M30: =IF($A30>NYears,"",'Engine A'!$R208)
A31: =18 | B31: =IF($A31>NYears,"",EDATE(StartMonth,$A31*12-1)) | C31: =IF($A31>NYears,"",'Engine A'!$E220) | D31: =IF($A31>NYears,"",'Engine A'!$F209) | E31: =IF($A31>NYears,"",'Engine A'!$G209) | F31: =IF($A31>NYears,"",'Engine A'!$S220) | G31: =IF($A31>NYears,"",'Engine A'!$S220-'Engine A'!$G209) | H31: =IF($A31>NYears,"",'Engine A'!$S220*'Engine A'!$E220) | I31: =IF($A31>NYears,"",'Engine A'!$K220) | J31: =IF($A31>NYears,"",'Engine A'!$P220) | K31: =IF($A31>NYears,"",'Engine A'!$Q220) | L31: =IF($A31>NYears,"",'Engine A'!$K220-'Engine A'!$P220-'Engine A'!$Q220) | M31: =IF($A31>NYears,"",'Engine A'!$R220)
A32: =19 | B32: =IF($A32>NYears,"",EDATE(StartMonth,$A32*12-1)) | C32: =IF($A32>NYears,"",'Engine A'!$E232) | D32: =IF($A32>NYears,"",'Engine A'!$F221) | E32: =IF($A32>NYears,"",'Engine A'!$G221) | F32: =IF($A32>NYears,"",'Engine A'!$S232) | G32: =IF($A32>NYears,"",'Engine A'!$S232-'Engine A'!$G221) | H32: =IF($A32>NYears,"",'Engine A'!$S232*'Engine A'!$E232) | I32: =IF($A32>NYears,"",'Engine A'!$K232) | J32: =IF($A32>NYears,"",'Engine A'!$P232) | K32: =IF($A32>NYears,"",'Engine A'!$Q232) | L32: =IF($A32>NYears,"",'Engine A'!$K232-'Engine A'!$P232-'Engine A'!$Q232) | M32: =IF($A32>NYears,"",'Engine A'!$R232)
A33: =20 | B33: =IF($A33>NYears,"",EDATE(StartMonth,$A33*12-1)) | C33: =IF($A33>NYears,"",'Engine A'!$E244) | D33: =IF($A33>NYears,"",'Engine A'!$F233) | E33: =IF($A33>NYears,"",'Engine A'!$G233) | F33: =IF($A33>NYears,"",'Engine A'!$S244) | G33: =IF($A33>NYears,"",'Engine A'!$S244-'Engine A'!$G233) | H33: =IF($A33>NYears,"",'Engine A'!$S244*'Engine A'!$E244) | I33: =IF($A33>NYears,"",'Engine A'!$K244) | J33: =IF($A33>NYears,"",'Engine A'!$P244) | K33: =IF($A33>NYears,"",'Engine A'!$Q244) | L33: =IF($A33>NYears,"",'Engine A'!$K244-'Engine A'!$P244-'Engine A'!$Q244) | M33: =IF($A33>NYears,"",'Engine A'!$R244)
A34: =21 | B34: =IF($A34>NYears,"",EDATE(StartMonth,$A34*12-1)) | C34: =IF($A34>NYears,"",'Engine A'!$E256) | D34: =IF($A34>NYears,"",'Engine A'!$F245) | E34: =IF($A34>NYears,"",'Engine A'!$G245) | F34: =IF($A34>NYears,"",'Engine A'!$S256) | G34: =IF($A34>NYears,"",'Engine A'!$S256-'Engine A'!$G245) | H34: =IF($A34>NYears,"",'Engine A'!$S256*'Engine A'!$E256) | I34: =IF($A34>NYears,"",'Engine A'!$K256) | J34: =IF($A34>NYears,"",'Engine A'!$P256) | K34: =IF($A34>NYears,"",'Engine A'!$Q256) | L34: =IF($A34>NYears,"",'Engine A'!$K256-'Engine A'!$P256-'Engine A'!$Q256) | M34: =IF($A34>NYears,"",'Engine A'!$R256)
A35: =22 | B35: =IF($A35>NYears,"",EDATE(StartMonth,$A35*12-1)) | C35: =IF($A35>NYears,"",'Engine A'!$E268) | D35: =IF($A35>NYears,"",'Engine A'!$F257) | E35: =IF($A35>NYears,"",'Engine A'!$G257) | F35: =IF($A35>NYears,"",'Engine A'!$S268) | G35: =IF($A35>NYears,"",'Engine A'!$S268-'Engine A'!$G257) | H35: =IF($A35>NYears,"",'Engine A'!$S268*'Engine A'!$E268) | I35: =IF($A35>NYears,"",'Engine A'!$K268) | J35: =IF($A35>NYears,"",'Engine A'!$P268) | K35: =IF($A35>NYears,"",'Engine A'!$Q268) | L35: =IF($A35>NYears,"",'Engine A'!$K268-'Engine A'!$P268-'Engine A'!$Q268) | M35: =IF($A35>NYears,"",'Engine A'!$R268)
A36: =23 | B36: =IF($A36>NYears,"",EDATE(StartMonth,$A36*12-1)) | C36: =IF($A36>NYears,"",'Engine A'!$E280) | D36: =IF($A36>NYears,"",'Engine A'!$F269) | E36: =IF($A36>NYears,"",'Engine A'!$G269) | F36: =IF($A36>NYears,"",'Engine A'!$S280) | G36: =IF($A36>NYears,"",'Engine A'!$S280-'Engine A'!$G269) | H36: =IF($A36>NYears,"",'Engine A'!$S280*'Engine A'!$E280) | I36: =IF($A36>NYears,"",'Engine A'!$K280) | J36: =IF($A36>NYears,"",'Engine A'!$P280) | K36: =IF($A36>NYears,"",'Engine A'!$Q280) | L36: =IF($A36>NYears,"",'Engine A'!$K280-'Engine A'!$P280-'Engine A'!$Q280) | M36: =IF($A36>NYears,"",'Engine A'!$R280)
A37: =24 | B37: =IF($A37>NYears,"",EDATE(StartMonth,$A37*12-1)) | C37: =IF($A37>NYears,"",'Engine A'!$E292) | D37: =IF($A37>NYears,"",'Engine A'!$F281) | E37: =IF($A37>NYears,"",'Engine A'!$G281) | F37: =IF($A37>NYears,"",'Engine A'!$S292) | G37: =IF($A37>NYears,"",'Engine A'!$S292-'Engine A'!$G281) | H37: =IF($A37>NYears,"",'Engine A'!$S292*'Engine A'!$E292) | I37: =IF($A37>NYears,"",'Engine A'!$K292) | J37: =IF($A37>NYears,"",'Engine A'!$P292) | K37: =IF($A37>NYears,"",'Engine A'!$Q292) | L37: =IF($A37>NYears,"",'Engine A'!$K292-'Engine A'!$P292-'Engine A'!$Q292) | M37: =IF($A37>NYears,"",'Engine A'!$R292)
A38: =25 | B38: =IF($A38>NYears,"",EDATE(StartMonth,$A38*12-1)) | C38: =IF($A38>NYears,"",'Engine A'!$E304) | D38: =IF($A38>NYears,"",'Engine A'!$F293) | E38: =IF($A38>NYears,"",'Engine A'!$G293) | F38: =IF($A38>NYears,"",'Engine A'!$S304) | G38: =IF($A38>NYears,"",'Engine A'!$S304-'Engine A'!$G293) | H38: =IF($A38>NYears,"",'Engine A'!$S304*'Engine A'!$E304) | I38: =IF($A38>NYears,"",'Engine A'!$K304) | J38: =IF($A38>NYears,"",'Engine A'!$P304) | K38: =IF($A38>NYears,"",'Engine A'!$Q304) | L38: =IF($A38>NYears,"",'Engine A'!$K304-'Engine A'!$P304-'Engine A'!$Q304) | M38: =IF($A38>NYears,"",'Engine A'!$R304)
A39: =26 | B39: =IF($A39>NYears,"",EDATE(StartMonth,$A39*12-1)) | C39: =IF($A39>NYears,"",'Engine A'!$E316) | D39: =IF($A39>NYears,"",'Engine A'!$F305) | E39: =IF($A39>NYears,"",'Engine A'!$G305) | F39: =IF($A39>NYears,"",'Engine A'!$S316) | G39: =IF($A39>NYears,"",'Engine A'!$S316-'Engine A'!$G305) | H39: =IF($A39>NYears,"",'Engine A'!$S316*'Engine A'!$E316) | I39: =IF($A39>NYears,"",'Engine A'!$K316) | J39: =IF($A39>NYears,"",'Engine A'!$P316) | K39: =IF($A39>NYears,"",'Engine A'!$Q316) | L39: =IF($A39>NYears,"",'Engine A'!$K316-'Engine A'!$P316-'Engine A'!$Q316) | M39: =IF($A39>NYears,"",'Engine A'!$R316)
A40: =27 | B40: =IF($A40>NYears,"",EDATE(StartMonth,$A40*12-1)) | C40: =IF($A40>NYears,"",'Engine A'!$E328) | D40: =IF($A40>NYears,"",'Engine A'!$F317) | E40: =IF($A40>NYears,"",'Engine A'!$G317) | F40: =IF($A40>NYears,"",'Engine A'!$S328) | G40: =IF($A40>NYears,"",'Engine A'!$S328-'Engine A'!$G317) | H40: =IF($A40>NYears,"",'Engine A'!$S328*'Engine A'!$E328) | I40: =IF($A40>NYears,"",'Engine A'!$K328) | J40: =IF($A40>NYears,"",'Engine A'!$P328) | K40: =IF($A40>NYears,"",'Engine A'!$Q328) | L40: =IF($A40>NYears,"",'Engine A'!$K328-'Engine A'!$P328-'Engine A'!$Q328) | M40: =IF($A40>NYears,"",'Engine A'!$R328)
A41: =28 | B41: =IF($A41>NYears,"",EDATE(StartMonth,$A41*12-1)) | C41: =IF($A41>NYears,"",'Engine A'!$E340) | D41: =IF($A41>NYears,"",'Engine A'!$F329) | E41: =IF($A41>NYears,"",'Engine A'!$G329) | F41: =IF($A41>NYears,"",'Engine A'!$S340) | G41: =IF($A41>NYears,"",'Engine A'!$S340-'Engine A'!$G329) | H41: =IF($A41>NYears,"",'Engine A'!$S340*'Engine A'!$E340) | I41: =IF($A41>NYears,"",'Engine A'!$K340) | J41: =IF($A41>NYears,"",'Engine A'!$P340) | K41: =IF($A41>NYears,"",'Engine A'!$Q340) | L41: =IF($A41>NYears,"",'Engine A'!$K340-'Engine A'!$P340-'Engine A'!$Q340) | M41: =IF($A41>NYears,"",'Engine A'!$R340)
A42: =29 | B42: =IF($A42>NYears,"",EDATE(StartMonth,$A42*12-1)) | C42: =IF($A42>NYears,"",'Engine A'!$E352) | D42: =IF($A42>NYears,"",'Engine A'!$F341) | E42: =IF($A42>NYears,"",'Engine A'!$G341) | F42: =IF($A42>NYears,"",'Engine A'!$S352) | G42: =IF($A42>NYears,"",'Engine A'!$S352-'Engine A'!$G341) | H42: =IF($A42>NYears,"",'Engine A'!$S352*'Engine A'!$E352) | I42: =IF($A42>NYears,"",'Engine A'!$K352) | J42: =IF($A42>NYears,"",'Engine A'!$P352) | K42: =IF($A42>NYears,"",'Engine A'!$Q352) | L42: =IF($A42>NYears,"",'Engine A'!$K352-'Engine A'!$P352-'Engine A'!$Q352) | M42: =IF($A42>NYears,"",'Engine A'!$R352)
...

Sheet Engine A
A1: Monthly engine — Scenario A
A2: Monthly return: | B2: =RateA | D2: One row per month. Returns accrue on DEPLOYED capital only; idle cash earns nothing until it funds a whole lot.
A4: Month # | B4: Month | C4: Yr | D4: M-in-yr | E4: Lot value | F4: Opening corpus | G4: Lots | H4: Deployed capital | I4: Idle cash | J4: Profit (month) | K4: Profit YTD | L4: Profit this qtr | M4: Slab income | N4: Tax rate | O4: Tax deducted | P4: Tax YTD | Q4: Withdrawal | R4: Closing corpus | S4: Lots at close
A5: =1 | B5: =IF($A5>NYears*12,"",EDATE(StartMonth,$A5-1)) | C5: =IF($A5>NYears*12,"",INT(($A5-1)/12)+1) | D5: =IF($A5>NYears*12,"",MOD($A5-1,12)+1) | E5: =IF($A5>NYears*12,"",LotValue0*(1+LotGrowth)^($C5-1)) | F5: =IF($A5>NYears*12,"",IF($A5=1,InitInvest,$R4)) | G5: =IF($A5>NYears*12,"",INT($F5/$E5)) | H5: =IF($A5>NYears*12,"",$G5*$E5) | I5: =IF($A5>NYears*12,"",$F5-$H5) | J5: =IF($A5>NYears*12,"",$H5*RateA) | K5: =IF($A5>NYears*12,"",IF($D5=1,$J5,$K4+$J5)) | L5: =IF($A5>NYears*12,"",IF(MOD($D5,3)=0,SUM($J3:$J5),0)) | M5: =IF($A5>NYears*12,"",IF(TaxFreq="Quarterly",$K5*12/$D5,$K5)) | N5: =IF($A5>NYears*12,"",LOOKUP($M5,TaxLower,TaxRate)) | O5: =IF($A5>NYears*12,"",IF(TaxFreq="Quarterly",IF(MOD($D5,3)=0,$L5*$N5,0),IF($D5=12,$K5*$N5,0))) | P5: =IF($A5>NYears*12,"",IF($D5=1,$O5,$P4+$O5)) | Q5: =IF($A5>NYears*12,"",IF($D5=12,MIN(WdrPct*IF(WdrBase="Post-tax profit",$K5-$P5,$K5),WdrCap),0)) | R5: =IF($A5>NYears*12,"",$F5+$J5-$O5-$Q5) | S5: =IF($A5>NYears*12,"",INT($R5/$E5))
A6: =2 | B6: =IF($A6>NYears*12,"",EDATE(StartMonth,$A6-1)) | C6: =IF($A6>NYears*12,"",INT(($A6-1)/12)+1) | D6: =IF($A6>NYears*12,"",MOD($A6-1,12)+1) | E6: =IF($A6>NYears*12,"",LotValue0*(1+LotGrowth)^($C6-1)) | F6: =IF($A6>NYears*12,"",IF($A6=1,InitInvest,$R5)) | G6: =IF($A6>NYears*12,"",INT($F6/$E6)) | H6: =IF($A6>NYears*12,"",$G6*$E6) | I6: =IF($A6>NYears*12,"",$F6-$H6) | J6: =IF($A6>NYears*12,"",$H6*RateA) | K6: =IF($A6>NYears*12,"",IF($D6=1,$J6,$K5+$J6)) | L6: =IF($A6>NYears*12,"",IF(MOD($D6,3)=0,SUM($J4:$J6),0)) | M6: =IF($A6>NYears*12,"",IF(TaxFreq="Quarterly",$K6*12/$D6,$K6)) | N6: =IF($A6>NYears*12,"",LOOKUP($M6,TaxLower,TaxRate)) | O6: =IF($A6>NYears*12,"",IF(TaxFreq="Quarterly",IF(MOD($D6,3)=0,$L6*$N6,0),IF($D6=12,$K6*$N6,0))) | P6: =IF($A6>NYears*12,"",IF($D6=1,$O6,$P5+$O6)) | Q6: =IF($A6>NYears*12,"",IF($D6=12,MIN(WdrPct*IF(WdrBase="Post-tax profit",$K6-$P6,$K6),WdrCap),0)) | R6: =IF($A6>NYears*12,"",$F6+$J6-$O6-$Q6) | S6: =IF($A6>NYears*12,"",INT($R6/$E6))
A7: =3 | B7: =IF($A7>NYears*12,"",EDATE(StartMonth,$A7-1)) | C7: =IF($A7>NYears*12,"",INT(($A7-1)/12)+1) | D7: =IF($A7>NYears*12,"",MOD($A7-1,12)+1) | E7: =IF($A7>NYears*12,"",LotValue0*(1+LotGrowth)^($C7-1)) | F7: =IF($A7>NYears*12,"",IF($A7=1,InitInvest,$R6)) | G7: =IF($A7>NYears*12,"",INT($F7/$E7)) | H7: =IF($A7>NYears*12,"",$G7*$E7) | I7: =IF($A7>NYears*12,"",$F7-$H7) | J7: =IF($A7>NYears*12,"",$H7*RateA) | K7: =IF($A7>NYears*12,"",IF($D7=1,$J7,$K6+$J7)) | L7: =IF($A7>NYears*12,"",IF(MOD($D7,3)=0,SUM($J5:$J7),0)) | M7: =IF($A7>NYears*12,"",IF(TaxFreq="Quarterly",$K7*12/$D7,$K7)) | N7: =IF($A7>NYears*12,"",LOOKUP($M7,TaxLower,TaxRate)) | O7: =IF($A7>NYears*12,"",IF(TaxFreq="Quarterly",IF(MOD($D7,3)=0,$L7*$N7,0),IF($D7=12,$K7*$N7,0))) | P7: =IF($A7>NYears*12,"",IF($D7=1,$O7,$P6+$O7)) | Q7: =IF($A7>NYears*12,"",IF($D7=12,MIN(WdrPct*IF(WdrBase="Post-tax profit",$K7-$P7,$K7),WdrCap),0)) | R7: =IF($A7>NYears*12,"",$F7+$J7-$O7-$Q7) | S7: =IF($A7>NYears*12,"",INT($R7/$E7))
A8: =4 | B8: =IF($A8>NYears*12,"",EDATE(StartMonth,$A8-1)) | C8: =IF($A8>NYears*12,"",INT(($A8-1)/12)+1) | D8: =IF($A8>NYears*12,"",MOD($A8-1,12)+1) | E8: =IF($A8>NYears*12,"",LotValue0*(1+LotGrowth)^($C8-1)) | F8: =IF($A8>NYears*12,"",IF($A8=1,InitInvest,$R7)) | G8: =IF($A8>NYears*12,"",INT($F8/$E8)) | H8: =IF($A8>NYears*12,"",$G8*$E8) | I8: =IF($A8>NYears*12,"",$F8-$H8) | J8: =IF($A8>NYears*12,"",$H8*RateA) | K8: =IF($A8>NYears*12,"",IF($D8=1,$J8,$K7+$J8)) | L8: =IF($A8>NYears*12,"",IF(MOD($D8,3)=0,SUM($J6:$J8),0)) | M8: =IF($A8>NYears*12,"",IF(TaxFreq="Quarterly",$K8*12/$D8,$K8)) | N8: =IF($A8>NYears*12,"",LOOKUP($M8,TaxLower,TaxRate)) | O8: =IF($A8>NYears*12,"",IF(TaxFreq="Quarterly",IF(MOD($D8,3)=0,$L8*$N8,0),IF($D8=12,$K8*$N8,0))) | P8: =IF($A8>NYears*12,"",IF($D8=1,$O8,$P7+$O8)) | Q8: =IF($A8>NYears*12,"",IF($D8=12,MIN(WdrPct*IF(WdrBase="Post-tax profit",$K8-$P8,$K8),WdrCap),0)) | R8: =IF($A8>NYears*12,"",$F8+$J8-$O8-$Q8) | S8: =IF($A8>NYears*12,"",INT($R8/$E8))
A9: =5 | B9: =IF($A9>NYears*12,"",EDATE(StartMonth,$A9-1)) | C9: =IF($A9>NYears*12,"",INT(($A9-1)/12)+1) | D9: =IF($A9>NYears*12,"",MOD($A9-1,12)+1) | E9: =IF($A9>NYears*12,"",LotValue0*(1+LotGrowth)^($C9-1)) | F9: =IF($A9>NYears*12,"",IF($A9=1,InitInvest,$R8)) | G9: =IF($A9>NYears*12,"",INT($F9/$E9)) | H9: =IF($A9>NYears*12,"",$G9*$E9) | I9: =IF($A9>NYears*12,"",$F9-$H9) | J9: =IF($A9>NYears*12,"",$H9*RateA) | K9: =IF($A9>NYears*12,"",IF($D9=1,$J9,$K8+$J9)) | L9: =IF($A9>NYears*12,"",IF(MOD($D9,3)=0,SUM($J7:$J9),0)) | M9: =IF($A9>NYears*12,"",IF(TaxFreq="Quarterly",$K9*12/$D9,$K9)) | N9: =IF($A9>NYears*12,"",LOOKUP($M9,TaxLower,TaxRate)) | O9: =IF($A9>NYears*12,"",IF(TaxFreq="Quarterly",IF(MOD($D9,3)=0,$L9*$N9,0),IF($D9=12,$K9*$N9,0))) | P9: =IF($A9>NYears*12,"",IF($D9=1,$O9,$P8+$O9)) | Q9: =IF($A9>NYears*12,"",IF($D9=12,MIN(WdrPct*IF(WdrBase="Post-tax profit",$K9-$P9,$K9),WdrCap),0)) | R9: =IF($A9>NYears*12,"",$F9+$J9-$O9-$Q9) | S9: =IF($A9>NYears*12,"",INT($R9/$E9))
A10: =6 | B10: =IF($A10>NYears*12,"",EDATE(StartMonth,$A10-1)) | C10: =IF($A10>NYears*12,"",INT(($A10-1)/12)+1) | D10: =IF($A10>NYears*12,"",MOD($A10-1,12)+1) | E10: =IF($A10>NYears*12,"",LotValue0*(1+LotGrowth)^($C10-1)) | F10: =IF($A10>NYears*12,"",IF($A10=1,InitInvest,$R9)) | G10: =IF($A10>NYears*12,"",INT($F10/$E10)) | H10: =IF($A10>NYears*12,"",$G10*$E10) | I10: =IF($A10>NYears*12,"",$F10-$H10) | J10: =IF($A10>NYears*12,"",$H10*RateA) | K10: =IF($A10>NYears*12,"",IF($D10=1,$J10,$K9+$J10)) | L10: =IF($A10>NYears*12,"",IF(MOD($D10,3)=0,SUM($J8:$J10),0)) | M10: =IF($A10>NYears*12,"",IF(TaxFreq="Quarterly",$K10*12/$D10,$K10)) | N10: =IF($A10>NYears*12,"",LOOKUP($M10,TaxLower,TaxRate)) | O10: =IF($A10>NYears*12,"",IF(TaxFreq="Quarterly",IF(MOD($D10,3)=0,$L10*$N10,0),IF($D10=12,$K10*$N10,0))) | P10: =IF($A10>NYears*12,"",IF($D10=1,$O10,$P9+$O10)) | Q10: =IF($A10>NYears*12,"",IF($D10=12,MIN(WdrPct*IF(WdrBase="Post-tax profit",$K10-$P10,$K10),WdrCap),0)) | R10: =IF($A10>NYears*12,"",$F10+$J10-$O10-$Q10) | S10: =IF($A10>NYears*12,"",INT($R10/$E10))
A11: =7 | B11: =IF($A11>NYears*12,"",EDATE(StartMonth,$A11-1)) | C11: =IF($A11>NYears*12,"",INT(($A11-1)/12)+1) | D11: =IF($A11>NYears*12,"",MOD($A11-1,12)+1) | E11: =IF($A11>NYears*12,"",LotValue0*(1+LotGrowth)^($C11-1)) | F11: =IF($A11>NYears*12,"",IF($A11=1,InitInvest,$R10)) | G11: =IF($A11>NYears*12,"",INT($F11/$E11)) | H11: =IF($A11>NYears*12,"",$G11*$E11) | I11: =IF($A11>NYears*12,"",$F11-$H11) | J11: =IF($A11>NYears*12,"",$H11*RateA) | K11: =IF($A11>NYears*12,"",IF($D11=1,$J11,$K10+$J11)) | L11: =IF($A11>NYears*12,"",IF(MOD($D11,3)=0,SUM($J9:$J11),0)) | M11: =IF($A11>NYears*12,"",IF(TaxFreq="Quarterly",$K11*12/$D11,$K11)) | N11: =IF($A11>NYears*12,"",LOOKUP($M11,TaxLower,TaxRate)) | O11: =IF($A11>NYears*12,"",IF(TaxFreq="Quarterly",IF(MOD($D11,3)=0,$L11*$N11,0),IF($D11=12,$K11*$N11,0))) | P11: =IF($A11>NYears*12,"",IF($D11=1,$O11,$P10+$O11)) | Q11: =IF($A11>NYears*12,"",IF($D11=12,MIN(WdrPct*IF(WdrBase="Post-tax profit",$K11-$P11,$K11),WdrCap),0)) | R11: =IF($A11>NYears*12,"",$F11+$J11-$O11-$Q11) | S11: =IF($A11>NYears*12,"",INT($R11/$E11))
A12: =8 | B12: =IF($A12>NYears*12,"",EDATE(StartMonth,$A12-1)) | C12: =IF($A12>NYears*12,"",INT(($A12-1)/12)+1) | D12: =IF($A12>NYears*12,"",MOD($A12-1,12)+1) | E12: =IF($A12>NYears*12,"",LotValue0*(1+LotGrowth)^($C12-1)) | F12: =IF($A12>NYears*12,"",IF($A12=1,InitInvest,$R11)) | G12: =IF($A12>NYears*12,"",INT($F12/$E12)) | H12: =IF($A12>NYears*12,"",$G12*$E12) | I12: =IF($A12>NYears*12,"",$F12-$H12) | J12: =IF($A12>NYears*12,"",$H12*RateA) | K12: =IF($A12>NYears*12,"",IF($D12=1,$J12,$K11+$J12)) | L12: =IF($A12>NYears*12,"",IF(MOD($D12,3)=0,SUM($J10:$J12),0)) | M12: =IF($A12>NYears*12,"",IF(TaxFreq="Quarterly",$K12*12/$D12,$K12)) | N12: =IF($A12>NYears*12,"",LOOKUP($M12,TaxLower,TaxRate)) | O12: =IF($A12>NYears*12,"",IF(TaxFreq="Quarterly",IF(MOD($D12,3)=0,$L12*$N12,0),IF($D12=12,$K12*$N12,0))) | P12: =IF($A12>NYears*12,"",IF($D12=1,$O12,$P11+$O12)) | Q12: =IF($A12>NYears*12,"",IF($D12=12,MIN(WdrPct*IF(WdrBase="Post-tax profit",$K12-$P12,$K12),WdrCap),0)) | R12: =IF($A12>NYears*12,"",$F12+$J12-$O12-$Q12) | S12: =IF($A12>NYears*12,"",INT($R12/$E12))
A13: =9 | B13: =IF($A13>NYears*12,"",EDATE(StartMonth,$A13-1)) | C13: =IF($A13>NYears*12,"",INT(($A13-1)/12)+1) | D13: =IF($A13>NYears*12,"",MOD($A13-1,12)+1) | E13: =IF($A13>NYears*12,"",LotValue0*(1+LotGrowth)^($C13-1)) | F13: =IF($A13>NYears*12,"",IF($A13=1,InitInvest,$R12)) | G13: =IF($A13>NYears*12,"",INT($F13/$E13)) | H13: =IF($A13>NYears*12,"",$G13*$E13) | I13: =IF($A13>NYears*12,"",$F13-$H13) | J13: =IF($A13>NYears*12,"",$H13*RateA) | K13: =IF($A13>NYears*12,"",IF($D13=1,$J13,$K12+$J13)) | L13: =IF($A13>NYears*12,"",IF(MOD($D13,3)=0,SUM($J11:$J13),0)) | M13: =IF($A13>NYears*12,"",IF(TaxFreq="Quarterly",$K13*12/$D13,$K13)) | N13: =IF($A13>NYears*12,"",LOOKUP($M13,TaxLower,TaxRate)) | O13: =IF($A13>NYears*12,"",IF(TaxFreq="Quarterly",IF(MOD($D13,3)=0,$L13*$N13,0),IF($D13=12,$K13*$N13,0))) | P13: =IF($A13>NYears*12,"",IF($D13=1,$O13,$P12+$O13)) | Q13: =IF($A13>NYears*12,"",IF($D13=12,MIN(WdrPct*IF(WdrBase="Post-tax profit",$K13-$P13,$K13),WdrCap),0)) | R13: =IF($A13>NYears*12,"",$F13+$J13-$O13-$Q13) | S13: =IF($A13>NYears*12,"",INT($R13/$E13))
A14: =10 | B14: =IF($A14>NYears*12,"",EDATE(StartMonth,$A14-1)) | C14: =IF($A14>NYears*12,"",INT(($A14-1)/12)+1) | D14: =IF($A14>NYears*12,"",MOD($A14-1,12)+1) | E14: =IF($A14>NYears*12,"",LotValue0*(1+LotGrowth)^($C14-1)) | F14: =IF($A14>NYears*12,"",IF($A14=1,InitInvest,$R13)) | G14: =IF($A14>NYears*12,"",INT($F14/$E14)) | H14: =IF($A14>NYears*12,"",$G14*$E14) | I14: =IF($A14>NYears*12,"",$F14-$H14) | J14: =IF($A14>NYears*12,"",$H14*RateA) | K14: =IF($A14>NYears*12,"",IF($D14=1,$J14,$K13+$J14)) | L14: =IF($A14>NYears*12,"",IF(MOD($D14,3)=0,SUM($J12:$J14),0)) | M14: =IF($A14>NYears*12,"",IF(TaxFreq="Quarterly",$K14*12/$D14,$K14)) | N14: =IF($A14>NYears*12,"",LOOKUP($M14,TaxLower,TaxRate)) | O14: =IF($A14>NYears*12,"",IF(TaxFreq="Quarterly",IF(MOD($D14,3)=0,$L14*$N14,0),IF($D14=12,$K14*$N14,0))) | P14: =IF($A14>NYears*12,"",IF($D14=1,$O14,$P13+$O14)) | Q14: =IF($A14>NYears*12,"",IF($D14=12,MIN(WdrPct*IF(WdrBase="Post-tax profit",$K14-$P14,$K14),WdrCap),0)) | R14: =IF($A14>NYears*12,"",$F14+$J14-$O14-$Q14) | S14: =IF($A14>NYears*12,"",INT($R14/$E14))
A15: =11 | B15: =IF($A15>NYears*12,"",EDATE(StartMonth,$A15-1)) | C15: =IF($A15>NYears*12,"",INT(($A15-1)/12)+1) | D15: =IF($A15>NYears*12,"",MOD($A15-1,12)+1) | E15: =IF($A15>NYears*12,"",LotValue0*(1+LotGrowth)^($C15-1)) | F15: =IF($A15>NYears*12,"",IF($A15=1,InitInvest,$R14)) | G15: =IF($A15>NYears*12,"",INT($F15/$E15)) | H15: =IF($A15>NYears*12,"",$G15*$E15) | I15: =IF($A15>NYears*12,"",$F15-$H15) | J15: =IF($A15>NYears*12,"",$H15*RateA) | K15: =IF($A15>NYears*12,"",IF($D15=1,$J15,$K14+$J15)) | L15: =IF($A15>NYears*12,"",IF(MOD($D15,3)=0,SUM($J13:$J15),0)) | M15: =IF($A15>NYears*12,"",IF(TaxFreq="Quarterly",$K15*12/$D15,$K15)) | N15: =IF($A15>NYears*12,"",LOOKUP($M15,TaxLower,TaxRate)) | O15: =IF($A15>NYears*12,"",IF(TaxFreq="Quarterly",IF(MOD($D15,3)=0,$L15*$N15,0),IF($D15=12,$K15*$N15,0))) | P15: =IF($A15>NYears*12,"",IF($D15=1,$O15,$P14+$O15)) | Q15: =IF($A15>NYears*12,"",IF($D15=12,MIN(WdrPct*IF(WdrBase="Post-tax profit",$K15-$P15,$K15),WdrCap),0)) | R15: =IF($A15>NYears*12,"",$F15+$J15-$O15-$Q15) | S15: =IF($A15>NYears*12,"",INT($R15/$E15))
A16: =12 | B16: =IF($A16>NYears*12,"",EDATE(StartMonth,$A16-1)) | C16: =IF($A16>NYears*12,"",INT(($A16-1)/12)+1) | D16: =IF($A16>NYears*12,"",MOD($A16-1,12)+1) | E16: =IF($A16>NYears*12,"",LotValue0*(1+LotGrowth)^($C16-1)) | F16: =IF($A16>NYears*12,"",IF($A16=1,InitInvest,$R15)) | G16: =IF($A16>NYears*12,"",INT($F16/$E16)) | H16: =IF($A16>NYears*12,"",$G16*$E16) | I16: =IF($A16>NYears*12,"",$F16-$H16) | J16: =IF($A16>NYears*12,"",$H16*RateA) | K16: =IF($A16>NYears*12,"",IF($D16=1,$J16,$K15+$J16)) | L16: =IF($A16>NYears*12,"",IF(MOD($D16,3)=0,SUM($J14:$J16),0)) | M16: =IF($A16>NYears*12,"",IF(TaxFreq="Quarterly",$K16*12/$D16,$K16)) | N16: =IF($A16>NYears*12,"",LOOKUP($M16,TaxLower,TaxRate)) | O16: =IF($A16>NYears*12,"",IF(TaxFreq="Quarterly",IF(MOD($D16,3)=0,$L16*$N16,0),IF($D16=12,$K16*$N16,0))) | P16: =IF($A16>NYears*12,"",IF($D16=1,$O16,$P15+$O16)) | Q16: =IF($A16>NYears*12,"",IF($D16=12,MIN(WdrPct*IF(WdrBase="Post-tax profit",$K16-$P16,$K16),WdrCap),0)) | R16: =IF($A16>NYears*12,"",$F16+$J16-$O16-$Q16) | S16: =IF($A16>NYears*12,"",INT($R16/$E16))
A17: =13 | B17: =IF($A17>NYears*12,"",EDATE(StartMonth,$A17-1)) | C17: =IF($A17>NYears*12,"",INT(($A17-1)/12)+1) | D17: =IF($A17>NYears*12,"",MOD($A17-1,12)+1) | E17: =IF($A17>NYears*12,"",LotValue0*(1+LotGrowth)^($C17-1)) | F17: =IF($A17>NYears*12,"",IF($A17=1,InitInvest,$R16)) | G17: =IF($A17>NYears*12,"",INT($F17/$E17)) | H17: =IF($A17>NYears*12,"",$G17*$E17) | I17: =IF($A17>NYears*12,"",$F17-$H17) | J17: =IF($A17>NYears*12,"",$H17*RateA) | K17: =IF($A17>NYears*12,"",IF($D17=1,$J17,$K16+$J17)) | L17: =IF($A17>NYears*12,"",IF(MOD($D17,3)=0,SUM($J15:$J17),0)) | M17: =IF($A17>NYears*12,"",IF(TaxFreq="Quarterly",$K17*12/$D17,$K17)) | N17: =IF($A17>NYears*12,"",LOOKUP($M17,TaxLower,TaxRate)) | O17: =IF($A17>NYears*12,"",IF(TaxFreq="Quarterly",IF(MOD($D17,3)=0,$L17*$N17,0),IF($D17=12,$K17*$N17,0))) | P17: =IF($A17>NYears*12,"",IF($D17=1,$O17,$P16+$O17)) | Q17: =IF($A17>NYears*12,"",IF($D17=12,MIN(WdrPct*IF(WdrBase="Post-tax profit",$K17-$P17,$K17),WdrCap),0)) | R17: =IF($A17>NYears*12,"",$F17+$J17-$O17-$Q17) | S17: =IF($A17>NYears*12,"",INT($R17/$E17))
A18: =14 | B18: =IF($A18>NYears*12,"",EDATE(StartMonth,$A18-1)) | C18: =IF($A18>NYears*12,"",INT(($A18-1)/12)+1) | D18: =IF($A18>NYears*12,"",MOD($A18-1,12)+1) | E18: =IF($A18>NYears*12,"",LotValue0*(1+LotGrowth)^($C18-1)) | F18: =IF($A18>NYears*12,"",IF($A18=1,InitInvest,$R17)) | G18: =IF($A18>NYears*12,"",INT($F18/$E18)) | H18: =IF($A18>NYears*12,"",$G18*$E18) | I18: =IF($A18>NYears*12,"",$F18-$H18) | J18: =IF($A18>NYears*12,"",$H18*RateA) | K18: =IF($A18>NYears*12,"",IF($D18=1,$J18,$K17+$J18)) | L18: =IF($A18>NYears*12,"",IF(MOD($D18,3)=0,SUM($J16:$J18),0)) | M18: =IF($A18>NYears*12,"",IF(TaxFreq="Quarterly",$K18*12/$D18,$K18)) | N18: =IF($A18>NYears*12,"",LOOKUP($M18,TaxLower,TaxRate)) | O18: =IF($A18>NYears*12,"",IF(TaxFreq="Quarterly",IF(MOD($D18,3)=0,$L18*$N18,0),IF($D18=12,$K18*$N18,0))) | P18: =IF($A18>NYears*12,"",IF($D18=1,$O18,$P17+$O18)) | Q18: =IF($A18>NYears*12,"",IF($D18=12,MIN(WdrPct*IF(WdrBase="Post-tax profit",$K18-$P18,$K18),WdrCap),0)) | R18: =IF($A18>NYears*12,"",$F18+$J18-$O18-$Q18) | S18: =IF($A18>NYears*12,"",INT($R18/$E18))
A19: =15 | B19: =IF($A19>NYears*12,"",EDATE(StartMonth,$A19-1)) | C19: =IF($A19>NYears*12,"",INT(($A19-1)/12)+1) | D19: =IF($A19>NYears*12,"",MOD($A19-1,12)+1) | E19: =IF($A19>NYears*12,"",LotValue0*(1+LotGrowth)^($C19-1)) | F19: =IF($A19>NYears*12,"",IF($A19=1,InitInvest,$R18)) | G19: =IF($A19>NYears*12,"",INT($F19/$E19)) | H19: =IF($A19>NYears*12,"",$G19*$E19) | I19: =IF($A19>NYears*12,"",$F19-$H19) | J19: =IF($A19>NYears*12,"",$H19*RateA) | K19: =IF($A19>NYears*12,"",IF($D19=1,$J19,$K18+$J19)) | L19: =IF($A19>NYears*12,"",IF(MOD($D19,3)=0,SUM($J17:$J19),0)) | M19: =IF($A19>NYears*12,"",IF(TaxFreq="Quarterly",$K19*12/$D19,$K19)) | N19: =IF($A19>NYears*12,"",LOOKUP($M19,TaxLower,TaxRate)) | O19: =IF($A19>NYears*12,"",IF(TaxFreq="Quarterly",IF(MOD($D19,3)=0,$L19*$N19,0),IF($D19=12,$K19*$N19,0))) | P19: =IF($A19>NYears*12,"",IF($D19=1,$O19,$P18+$O19)) | Q19: =IF($A19>NYears*12,"",IF($D19=12,MIN(WdrPct*IF(WdrBase="Post-tax profit",$K19-$P19,$K19),WdrCap),0)) | R19: =IF($A19>NYears*12,"",$F19+$J19-$O19-$Q19) | S19: =IF($A19>NYears*12,"",INT($R19/$E19))
A20: =16 | B20: =IF($A20>NYears*12,"",EDATE(StartMonth,$A20-1)) | C20: =IF($A20>NYears*12,"",INT(($A20-1)/12)+1) | D20: =IF($A20>NYears*12,"",MOD($A20-1,12)+1) | E20: =IF($A20>NYears*12,"",LotValue0*(1+LotGrowth)^($C20-1)) | F20: =IF($A20>NYears*12,"",IF($A20=1,InitInvest,$R19)) | G20: =IF($A20>NYears*12,"",INT($F20/$E20)) | H20: =IF($A20>NYears*12,"",$G20*$E20) | I20: =IF($A20>NYears*12,"",$F20-$H20) | J20: =IF($A20>NYears*12,"",$H20*RateA) | K20: =IF($A20>NYears*12,"",IF($D20=1,$J20,$K19+$J20)) | L20: =IF($A20>NYears*12,"",IF(MOD($D20,3)=0,SUM($J18:$J20),0)) | M20: =IF($A20>NYears*12,"",IF(TaxFreq="Quarterly",$K20*12/$D20,$K20)) | N20: =IF($A20>NYears*12,"",LOOKUP($M20,TaxLower,TaxRate)) | O20: =IF($A20>NYears*12,"",IF(TaxFreq="Quarterly",IF(MOD($D20,3)=0,$L20*$N20,0),IF($D20=12,$K20*$N20,0))) | P20: =IF($A20>NYears*12,"",IF($D20=1,$O20,$P19+$O20)) | Q20: =IF($A20>NYears*12,"",IF($D20=12,MIN(WdrPct*IF(WdrBase="Post-tax profit",$K20-$P20,$K20),WdrCap),0)) | R20: =IF($A20>NYears*12,"",$F20+$J20-$O20-$Q20) | S20: =IF($A20>NYears*12,"",INT($R20/$E20))
A21: =17 | B21: =IF($A21>NYears*12,"",EDATE(StartMonth,$A21-1)) | C21: =IF($A21>NYears*12,"",INT(($A21-1)/12)+1) | D21: =IF($A21>NYears*12,"",MOD($A21-1,12)+1) | E21: =IF($A21>NYears*12,"",LotValue0*(1+LotGrowth)^($C21-1)) | F21: =IF($A21>NYears*12,"",IF($A21=1,InitInvest,$R20)) | G21: =IF($A21>NYears*12,"",INT($F21/$E21)) | H21: =IF($A21>NYears*12,"",$G21*$E21) | I21: =IF($A21>NYears*12,"",$F21-$H21) | J21: =IF($A21>NYears*12,"",$H21*RateA) | K21: =IF($A21>NYears*12,"",IF($D21=1,$J21,$K20+$J21)) | L21: =IF($A21>NYears*12,"",IF(MOD($D21,3)=0,SUM($J19:$J21),0)) | M21: =IF($A21>NYears*12,"",IF(TaxFreq="Quarterly",$K21*12/$D21,$K21)) | N21: =IF($A21>NYears*12,"",LOOKUP($M21,TaxLower,TaxRate)) | O21: =IF($A21>NYears*12,"",IF(TaxFreq="Quarterly",IF(MOD($D21,3)=0,$L21*$N21,0),IF($D21=12,$K21*$N21,0))) | P21: =IF($A21>NYears*12,"",IF($D21=1,$O21,$P20+$O21)) | Q21: =IF($A21>NYears*12,"",IF($D21=12,MIN(WdrPct*IF(WdrBase="Post-tax profit",$K21-$P21,$K21),WdrCap),0)) | R21: =IF($A21>NYears*12,"",$F21+$J21-$O21-$Q21) | S21: =IF($A21>NYears*12,"",INT($R21/$E21))
A22: =18 | B22: =IF($A22>NYears*12,"",EDATE(StartMonth,$A22-1)) | C22: =IF($A22>NYears*12,"",INT(($A22-1)/12)+1) | D22: =IF($A22>NYears*12,"",MOD($A22-1,12)+1) | E22: =IF($A22>NYears*12,"",LotValue0*(1+LotGrowth)^($C22-1)) | F22: =IF($A22>NYears*12,"",IF($A22=1,InitInvest,$R21)) | G22: =IF($A22>NYears*12,"",INT($F22/$E22)) | H22: =IF($A22>NYears*12,"",$G22*$E22) | I22: =IF($A22>NYears*12,"",$F22-$H22) | J22: =IF($A22>NYears*12,"",$H22*RateA) | K22: =IF($A22>NYears*12,"",IF($D22=1,$J22,$K21+$J22)) | L22: =IF($A22>NYears*12,"",IF(MOD($D22,3)=0,SUM($J20:$J22),0)) | M22: =IF($A22>NYears*12,"",IF(TaxFreq="Quarterly",$K22*12/$D22,$K22)) | N22: =IF($A22>NYears*12,"",LOOKUP($M22,TaxLower,TaxRate)) | O22: =IF($A22>NYears*12,"",IF(TaxFreq="Quarterly",IF(MOD($D22,3)=0,$L22*$N22,0),IF($D22=12,$K22*$N22,0))) | P22: =IF($A22>NYears*12,"",IF($D22=1,$O22,$P21+$O22)) | Q22: =IF($A22>NYears*12,"",IF($D22=12,MIN(WdrPct*IF(WdrBase="Post-tax profit",$K22-$P22,$K22),WdrCap),0)) | R22: =IF($A22>NYears*12,"",$F22+$J22-$O22-$Q22) | S22: =IF($A22>NYears*12,"",INT($R22/$E22))
A23: =19 | B23: =IF($A23>NYears*12,"",EDATE(StartMonth,$A23-1)) | C23: =IF($A23>NYears*12,"",INT(($A23-1)/12)+1) | D23: =IF($A23>NYears*12,"",MOD($A23-1,12)+1) | E23: =IF($A23>NYears*12,"",LotValue0*(1+LotGrowth)^($C23-1)) | F23: =IF($A23>NYears*12,"",IF($A23=1,InitInvest,$R22)) | G23: =IF($A23>NYears*12,"",INT($F23/$E23)) | H23: =IF($A23>NYears*12,"",$G23*$E23) | I23: =IF($A23>NYears*12,"",$F23-$H23) | J23: =IF($A23>NYears*12,"",$H23*RateA) | K23: =IF($A23>NYears*12,"",IF($D23=1,$J23,$K22+$J23)) | L23: =IF($A23>NYears*12,"",IF(MOD($D23,3)=0,SUM($J21:$J23),0)) | M23: =IF($A23>NYears*12,"",IF(TaxFreq="Quarterly",$K23*12/$D23,$K23)) | N23: =IF($A23>NYears*12,"",LOOKUP($M23,TaxLower,TaxRate)) | O23: =IF($A23>NYears*12,"",IF(TaxFreq="Quarterly",IF(MOD($D23,3)=0,$L23*$N23,0),IF($D23=12,$K23*$N23,0))) | P23: =IF($A23>NYears*12,"",IF($D23=1,$O23,$P22+$O23)) | Q23: =IF($A23>NYears*12,"",IF($D23=12,MIN(WdrPct*IF(WdrBase="Post-tax profit",$K23-$P23,$K23),WdrCap),0)) | R23: =IF($A23>NYears*12,"",$F23+$J23-$O23-$Q23) | S23: =IF($A23>NYears*12,"",INT($R23/$E23))
A24: =20 | B24: =IF($A24>NYears*12,"",EDATE(StartMonth,$A24-1)) | C24: =IF($A24>NYears*12,"",INT(($A24-1)/12)+1) | D24: =IF($A24>NYears*12,"",MOD($A24-1,12)+1) | E24: =IF($A24>NYears*12,"",LotValue0*(1+LotGrowth)^($C24-1)) | F24: =IF($A24>NYears*12,"",IF($A24=1,InitInvest,$R23)) | G24: =IF($A24>NYears*12,"",INT($F24/$E24)) | H24: =IF($A24>NYears*12,"",$G24*$E24) | I24: =IF($A24>NYears*12,"",$F24-$H24) | J24: =IF($A24>NYears*12,"",$H24*RateA) | K24: =IF($A24>NYears*12,"",IF($D24=1,$J24,$K23+$J24)) | L24: =IF($A24>NYears*12,"",IF(MOD($D24,3)=0,SUM($J22:$J24),0)) | M24: =IF($A24>NYears*12,"",IF(TaxFreq="Quarterly",$K24*12/$D24,$K24)) | N24: =IF($A24>NYears*12,"",LOOKUP($M24,TaxLower,TaxRate)) | O24: =IF($A24>NYears*12,"",IF(TaxFreq="Quarterly",IF(MOD($D24,3)=0,$L24*$N24,0),IF($D24=12,$K24*$N24,0))) | P24: =IF($A24>NYears*12,"",IF($D24=1,$O24,$P23+$O24)) | Q24: =IF($A24>NYears*12,"",IF($D24=12,MIN(WdrPct*IF(WdrBase="Post-tax profit",$K24-$P24,$K24),WdrCap),0)) | R24: =IF($A24>NYears*12,"",$F24+$J24-$O24-$Q24) | S24: =IF($A24>NYears*12,"",INT($R24/$E24))
A25: =21 | B25: =IF($A25>NYears*12,"",EDATE(StartMonth,$A25-1)) | C25: =IF($A25>NYears*12,"",INT(($A25-1)/12)+1) | D25: =IF($A25>NYears*12,"",MOD($A25-1,12)+1) | E25: =IF($A25>NYears*12,"",LotValue0*(1+LotGrowth)^($C25-1)) | F25: =IF($A25>NYears*12,"",IF($A25=1,InitInvest,$R24)) | G25: =IF($A25>NYears*12,"",INT($F25/$E25)) | H25: =IF($A25>NYears*12,"",$G25*$E25) | I25: =IF($A25>NYears*12,"",$F25-$H25) | J25: =IF($A25>NYears*12,"",$H25*RateA) | K25: =IF($A25>NYears*12,"",IF($D25=1,$J25,$K24+$J25)) | L25: =IF($A25>NYears*12,"",IF(MOD($D25,3)=0,SUM($J23:$J25),0)) | M25: =IF($A25>NYears*12,"",IF(TaxFreq="Quarterly",$K25*12/$D25,$K25)) | N25: =IF($A25>NYears*12,"",LOOKUP($M25,TaxLower,TaxRate)) | O25: =IF($A25>NYears*12,"",IF(TaxFreq="Quarterly",IF(MOD($D25,3)=0,$L25*$N25,0),IF($D25=12,$K25*$N25,0))) | P25: =IF($A25>NYears*12,"",IF($D25=1,$O25,$P24+$O25)) | Q25: =IF($A25>NYears*12,"",IF($D25=12,MIN(WdrPct*IF(WdrBase="Post-tax profit",$K25-$P25,$K25),WdrCap),0)) | R25: =IF($A25>NYears*12,"",$F25+$J25-$O25-$Q25) | S25: =IF($A25>NYears*12,"",INT($R25/$E25))
A26: =22 | B26: =IF($A26>NYears*12,"",EDATE(StartMonth,$A26-1)) | C26: =IF($A26>NYears*12,"",INT(($A26-1)/12)+1) | D26: =IF($A26>NYears*12,"",MOD($A26-1,12)+1) | E26: =IF($A26>NYears*12,"",LotValue0*(1+LotGrowth)^($C26-1)) | F26: =IF($A26>NYears*12,"",IF($A26=1,InitInvest,$R25)) | G26: =IF($A26>NYears*12,"",INT($F26/$E26)) | H26: =IF($A26>NYears*12,"",$G26*$E26) | I26: =IF($A26>NYears*12,"",$F26-$H26) | J26: =IF($A26>NYears*12,"",$H26*RateA) | K26: =IF($A26>NYears*12,"",IF($D26=1,$J26,$K25+$J26)) | L26: =IF($A26>NYears*12,"",IF(MOD($D26,3)=0,SUM($J24:$J26),0)) | M26: =IF($A26>NYears*12,"",IF(TaxFreq="Quarterly",$K26*12/$D26,$K26)) | N26: =IF($A26>NYears*12,"",LOOKUP($M26,TaxLower,TaxRate)) | O26: =IF($A26>NYears*12,"",IF(TaxFreq="Quarterly",IF(MOD($D26,3)=0,$L26*$N26,0),IF($D26=12,$K26*$N26,0))) | P26: =IF($A26>NYears*12,"",IF($D26=1,$O26,$P25+$O26)) | Q26: =IF($A26>NYears*12,"",IF($D26=12,MIN(WdrPct*IF(WdrBase="Post-tax profit",$K26-$P26,$K26),WdrCap),0)) | R26: =IF($A26>NYears*12,"",$F26+$J26-$O26-$Q26) | S26: =IF($A26>NYears*12,"",INT($R26/$E26))
A27: =23 | B27: =IF($A27>NYears*12,"",EDATE(StartMonth,$A27-1)) | C27: =IF($A27>NYears*12,"",INT(($A27-1)/12)+1) | D27: =IF($A27>NYears*12,"",MOD($A27-1,12)+1) | E27: =IF($A27>NYears*12,"",LotValue0*(1+LotGrowth)^($C27-1)) | F27: =IF($A27>NYears*12,"",IF($A27=1,InitInvest,$R26)) | G27: =IF($A27>NYears*12,"",INT($F27/$E27)) | H27: =IF($A27>NYears*12,"",$G27*$E27) | I27: =IF($A27>NYears*12,"",$F27-$H27) | J27: =IF($A27>NYears*12,"",$H27*RateA) | K27: =IF($A27>NYears*12,"",IF($D27=1,$J27,$K26+$J27)) | L27: =IF($A27>NYears*12,"",IF(MOD($D27,3)=0,SUM($J25:$J27),0)) | M27: =IF($A27>NYears*12,"",IF(TaxFreq="Quarterly",$K27*12/$D27,$K27)) | N27: =IF($A27>NYears*12,"",LOOKUP($M27,TaxLower,TaxRate)) | O27: =IF($A27>NYears*12,"",IF(TaxFreq="Quarterly",IF(MOD($D27,3)=0,$L27*$N27,0),IF($D27=12,$K27*$N27,0))) | P27: =IF($A27>NYears*12,"",IF($D27=1,$O27,$P26+$O27)) | Q27: =IF($A27>NYears*12,"",IF($D27=12,MIN(WdrPct*IF(WdrBase="Post-tax profit",$K27-$P27,$K27),WdrCap),0)) | R27: =IF($A27>NYears*12,"",$F27+$J27-$O27-$Q27) | S27: =IF($A27>NYears*12,"",INT($R27/$E27))
A28: =24 | B28: =IF($A28>NYears*12,"",EDATE(StartMonth,$A28-1)) | C28: =IF($A28>NYears*12,"",INT(($A28-1)/12)+1) | D28: =IF($A28>NYears*12,"",MOD($A28-1,12)+1) | E28: =IF($A28>NYears*12,"",LotValue0*(1+LotGrowth)^($C28-1)) | F28: =IF($A28>NYears*12,"",IF($A28=1,InitInvest,$R27)) | G28: =IF($A28>NYears*12,"",INT($F28/$E28)) | H28: =IF($A28>NYears*12,"",$G28*$E28) | I28: =IF($A28>NYears*12,"",$F28-$H28) | J28: =IF($A28>NYears*12,"",$H28*RateA) | K28: =IF($A28>NYears*12,"",IF($D28=1,$J28,$K27+$J28)) | L28: =IF($A28>NYears*12,"",IF(MOD($D28,3)=0,SUM($J26:$J28),0)) | M28: =IF($A28>NYears*12,"",IF(TaxFreq="Quarterly",$K28*12/$D28,$K28)) | N28: =IF($A28>NYears*12,"",LOOKUP($M28,TaxLower,TaxRate)) | O28: =IF($A28>NYears*12,"",IF(TaxFreq="Quarterly",IF(MOD($D28,3)=0,$L28*$N28,0),IF($D28=12,$K28*$N28,0))) | P28: =IF($A28>NYears*12,"",IF($D28=1,$O28,$P27+$O28)) | Q28: =IF($A28>NYears*12,"",IF($D28=12,MIN(WdrPct*IF(WdrBase="Post-tax profit",$K28-$P28,$K28),WdrCap),0)) | R28: =IF($A28>NYears*12,"",$F28+$J28-$O28-$Q28) | S28: =IF($A28>NYears*12,"",INT($R28/$E28))
A29: =25 | B29: =IF($A29>NYears*12,"",EDATE(StartMonth,$A29-1)) | C29: =IF($A29>NYears*12,"",INT(($A29-1)/12)+1) | D29: =IF($A29>NYears*12,"",MOD($A29-1,12)+1) | E29: =IF($A29>NYears*12,"",LotValue0*(1+LotGrowth)^($C29-1)) | F29: =IF($A29>NYears*12,"",IF($A29=1,InitInvest,$R28)) | G29: =IF($A29>NYears*12,"",INT($F29/$E29)) | H29: =IF($A29>NYears*12,"",$G29*$E29) | I29: =IF($A29>NYears*12,"",$F29-$H29) | J29: =IF($A29>NYears*12,"",$H29*RateA) | K29: =IF($A29>NYears*12,"",IF($D29=1,$J29,$K28+$J29)) | L29: =IF($A29>NYears*12,"",IF(MOD($D29,3)=0,SUM($J27:$J29),0)) | M29: =IF($A29>NYears*12,"",IF(TaxFreq="Quarterly",$K29*12/$D29,$K29)) | N29: =IF($A29>NYears*12,"",LOOKUP($M29,TaxLower,TaxRate)) | O29: =IF($A29>NYears*12,"",IF(TaxFreq="Quarterly",IF(MOD($D29,3)=0,$L29*$N29,0),IF($D29=12,$K29*$N29,0))) | P29: =IF($A29>NYears*12,"",IF($D29=1,$O29,$P28+$O29)) | Q29: =IF($A29>NYears*12,"",IF($D29=12,MIN(WdrPct*IF(WdrBase="Post-tax profit",$K29-$P29,$K29),WdrCap),0)) | R29: =IF($A29>NYears*12,"",$F29+$J29-$O29-$Q29) | S29: =IF($A29>NYears*12,"",INT($R29/$E29))
A30: =26 | B30: =IF($A30>NYears*12,"",EDATE(StartMonth,$A30-1)) | C30: =IF($A30>NYears*12,"",INT(($A30-1)/12)+1) | D30: =IF($A30>NYears*12,"",MOD($A30-1,12)+1) | E30: =IF($A30>NYears*12,"",LotValue0*(1+LotGrowth)^($C30-1)) | F30: =IF($A30>NYears*12,"",IF($A30=1,InitInvest,$R29)) | G30: =IF($A30>NYears*12,"",INT($F30/$E30)) | H30: =IF($A30>NYears*12,"",$G30*$E30) | I30: =IF($A30>NYears*12,"",$F30-$H30) | J30: =IF($A30>NYears*12,"",$H30*RateA) | K30: =IF($A30>NYears*12,"",IF($D30=1,$J30,$K29+$J30)) | L30: =IF($A30>NYears*12,"",IF(MOD($D30,3)=0,SUM($J28:$J30),0)) | M30: =IF($A30>NYears*12,"",IF(TaxFreq="Quarterly",$K30*12/$D30,$K30)) | N30: =IF($A30>NYears*12,"",LOOKUP($M30,TaxLower,TaxRate)) | O30: =IF($A30>NYears*12,"",IF(TaxFreq="Quarterly",IF(MOD($D30,3)=0,$L30*$N30,0),IF($D30=12,$K30*$N30,0))) | P30: =IF($A30>NYears*12,"",IF($D30=1,$O30,$P29+$O30)) | Q30: =IF($A30>NYears*12,"",IF($D30=12,MIN(WdrPct*IF(WdrBase="Post-tax profit",$K30-$P30,$K30),WdrCap),0)) | R30: =IF($A30>NYears*12,"",$F30+$J30-$O30-$Q30) | S30: =IF($A30>NYears*12,"",INT($R30/$E30))
A31: =27 | B31: =IF($A31>NYears*12,"",EDATE(StartMonth,$A31-1)) | C31: =IF($A31>NYears*12,"",INT(($A31-1)/12)+1) | D31: =IF($A31>NYears*12,"",MOD($A31-1,12)+1) | E31: =IF($A31>NYears*12,"",LotValue0*(1+LotGrowth)^($C31-1)) | F31: =IF($A31>NYears*12,"",IF($A31=1,InitInvest,$R30)) | G31: =IF($A31>NYears*12,"",INT($F31/$E31)) | H31: =IF($A31>NYears*12,"",$G31*$E31) | I31: =IF($A31>NYears*12,"",$F31-$H31) | J31: =IF($A31>NYears*12,"",$H31*RateA) | K31: =IF($A31>NYears*12,"",IF($D31=1,$J31,$K30+$J31)) | L31: =IF($A31>NYears*12,"",IF(MOD($D31,3)=0,SUM($J29:$J31),0)) | M31: =IF($A31>NYears*12,"",IF(TaxFreq="Quarterly",$K31*12/$D31,$K31)) | N31: =IF($A31>NYears*12,"",LOOKUP($M31,TaxLower,TaxRate)) | O31: =IF($A31>NYears*12,"",IF(TaxFreq="Quarterly",IF(MOD($D31,3)=0,$L31*$N31,0),IF($D31=12,$K31*$N31,0))) | P31: =IF($A31>NYears*12,"",IF($D31=1,$O31,$P30+$O31)) | Q31: =IF($A31>NYears*12,"",IF($D31=12,MIN(WdrPct*IF(WdrBase="Post-tax profit",$K31-$P31,$K31),WdrCap),0)) | R31: =IF($A31>NYears*12,"",$F31+$J31-$O31-$Q31) | S31: =IF($A31>NYears*12,"",INT($R31/$E31))
A32: =28 | B32: =IF($A32>NYears*12,"",EDATE(StartMonth,$A32-1)) | C32: =IF($A32>NYears*12,"",INT(($A32-1)/12)+1) | D32: =IF($A32>NYears*12,"",MOD($A32-1,12)+1) | E32: =IF($A32>NYears*12,"",LotValue0*(1+LotGrowth)^($C32-1)) | F32: =IF($A32>NYears*12,"",IF($A32=1,InitInvest,$R31)) | G32: =IF($A32>NYears*12,"",INT($F32/$E32)) | H32: =IF($A32>NYears*12,"",$G32*$E32) | I32: =IF($A32>NYears*12,"",$F32-$H32) | J32: =IF($A32>NYears*12,"",$H32*RateA) | K32: =IF($A32>NYears*12,"",IF($D32=1,$J32,$K31+$J32)) | L32: =IF($A32>NYears*12,"",IF(MOD($D32,3)=0,SUM($J30:$J32),0)) | M32: =IF($A32>NYears*12,"",IF(TaxFreq="Quarterly",$K32*12/$D32,$K32)) | N32: =IF($A32>NYears*12,"",LOOKUP($M32,TaxLower,TaxRate)) | O32: =IF($A32>NYears*12,"",IF(TaxFreq="Quarterly",IF(MOD($D32,3)=0,$L32*$N32,0),IF($D32=12,$K32*$N32,0))) | P32: =IF($A32>NYears*12,"",IF($D32=1,$O32,$P31+$O32)) | Q32: =IF($A32>NYears*12,"",IF($D32=12,MIN(WdrPct*IF(WdrBase="Post-tax profit",$K32-$P32,$K32),WdrCap),0)) | R32: =IF($A32>NYears*12,"",$F32+$J32-$O32-$Q32) | S32: =IF($A32>NYears*12,"",INT($R32/$E32))
A33: =29 | B33: =IF($A33>NYears*12,"",EDATE(StartMonth,$A33-1)) | C33: =IF($A33>NYears*12,"",INT(($A33-1)/12)+1) | D33: =IF($A33>NYears*12,"",MOD($A33-1,12)+1) | E33: =IF($A33>NYears*12,"",LotValue0*(1+LotGrowth)^($C33-1)) | F33: =IF($A33>NYears*12,"",IF($A33=1,InitInvest,$R32)) | G33: =IF($A33>NYears*12,"",INT($F33/$E33)) | H33: =IF($A33>NYears*12,"",$G33*$E33) | I33: =IF($A33>NYears*12,"",$F33-$H33) | J33: =IF($A33>NYears*12,"",$H33*RateA) | K33: =IF($A33>NYears*12,"",IF($D33=1,$J33,$K32+$J33)) | L33: =IF($A33>NYears*12,"",IF(MOD($D33,3)=0,SUM($J31:$J33),0)) | M33: =IF($A33>NYears*12,"",IF(TaxFreq="Quarterly",$K33*12/$D33,$K33)) | N33: =IF($A33>NYears*12,"",LOOKUP($M33,TaxLower,TaxRate)) | O33: =IF($A33>NYears*12,"",IF(TaxFreq="Quarterly",IF(MOD($D33,3)=0,$L33*$N33,0),IF($D33=12,$K33*$N33,0))) | P33: =IF($A33>NYears*12,"",IF($D33=1,$O33,$P32+$O33)) | Q33: =IF($A33>NYears*12,"",IF($D33=12,MIN(WdrPct*IF(WdrBase="Post-tax profit",$K33-$P33,$K33),WdrCap),0)) | R33: =IF($A33>NYears*12,"",$F33+$J33-$O33-$Q33) | S33: =IF($A33>NYears*12,"",INT($R33/$E33))
A34: =30 | B34: =IF($A34>NYears*12,"",EDATE(StartMonth,$A34-1)) | C34: =IF($A34>NYears*12,"",INT(($A34-1)/12)+1) | D34: =IF($A34>NYears*12,"",MOD($A34-1,12)+1) | E34: =IF($A34>NYears*12,"",LotValue0*(1+LotGrowth)^($C34-1)) | F34: =IF($A34>NYears*12,"",IF($A34=1,InitInvest,$R33)) | G34: =IF($A34>NYears*12,"",INT($F34/$E34)) | H34: =IF($A34>NYears*12,"",$G34*$E34) | I34: =IF($A34>NYears*12,"",$F34-$H34) | J34: =IF($A34>NYears*12,"",$H34*RateA) | K34: =IF($A34>NYears*12,"",IF($D34=1,$J34,$K33+$J34)) | L34: =IF($A34>NYears*12,"",IF(MOD($D34,3)=0,SUM($J32:$J34),0)) | M34: =IF($A34>NYears*12,"",IF(TaxFreq="Quarterly",$K34*12/$D34,$K34)) | N34: =IF($A34>NYears*12,"",LOOKUP($M34,TaxLower,TaxRate)) | O34: =IF($A34>NYears*12,"",IF(TaxFreq="Quarterly",IF(MOD($D34,3)=0,$L34*$N34,0),IF($D34=12,$K34*$N34,0))) | P34: =IF($A34>NYears*12,"",IF($D34=1,$O34,$P33+$O34)) | Q34: =IF($A34>NYears*12,"",IF($D34=12,MIN(WdrPct*IF(WdrBase="Post-tax profit",$K34-$P34,$K34),WdrCap),0)) | R34: =IF($A34>NYears*12,"",$F34+$J34-$O34-$Q34) | S34: =IF($A34>NYears*12,"",INT($R34/$E34))
A35: =31 | B35: =IF($A35>NYears*12,"",EDATE(StartMonth,$A35-1)) | C35: =IF($A35>NYears*12,"",INT(($A35-1)/12)+1) | D35: =IF($A35>NYears*12,"",MOD($A35-1,12)+1) | E35: =IF($A35>NYears*12,"",LotValue0*(1+LotGrowth)^($C35-1)) | F35: =IF($A35>NYears*12,"",IF($A35=1,InitInvest,$R34)) | G35: =IF($A35>NYears*12,"",INT($F35/$E35)) | H35: =IF($A35>NYears*12,"",$G35*$E35) | I35: =IF($A35>NYears*12,"",$F35-$H35) | J35: =IF($A35>NYears*12,"",$H35*RateA) | K35: =IF($A35>NYears*12,"",IF($D35=1,$J35,$K34+$J35)) | L35: =IF($A35>NYears*12,"",IF(MOD($D35,3)=0,SUM($J33:$J35),0)) | M35: =IF($A35>NYears*12,"",IF(TaxFreq="Quarterly",$K35*12/$D35,$K35)) | N35: =IF($A35>NYears*12,"",LOOKUP($M35,TaxLower,TaxRate)) | O35: =IF($A35>NYears*12,"",IF(TaxFreq="Quarterly",IF(MOD($D35,3)=0,$L35*$N35,0),IF($D35=12,$K35*$N35,0))) | P35: =IF($A35>NYears*12,"",IF($D35=1,$O35,$P34+$O35)) | Q35: =IF($A35>NYears*12,"",IF($D35=12,MIN(WdrPct*IF(WdrBase="Post-tax profit",$K35-$P35,$K35),WdrCap),0)) | R35: =IF($A35>NYears*12,"",$F35+$J35-$O35-$Q35) | S35: =IF($A35>NYears*12,"",INT($R35/$E35))
A36: =32 | B36: =IF($A36>NYears*12,"",EDATE(StartMonth,$A36-1)) | C36: =IF($A36>NYears*12,"",INT(($A36-1)/12)+1) | D36: =IF($A36>NYears*12,"",MOD($A36-1,12)+1) | E36: =IF($A36>NYears*12,"",LotValue0*(1+LotGrowth)^($C36-1)) | F36: =IF($A36>NYears*12,"",IF($A36=1,InitInvest,$R35)) | G36: =IF($A36>NYears*12,"",INT($F36/$E36)) | H36: =IF($A36>NYears*12,"",$G36*$E36) | I36: =IF($A36>NYears*12,"",$F36-$H36) | J36: =IF($A36>NYears*12,"",$H36*RateA) | K36: =IF($A36>NYears*12,"",IF($D36=1,$J36,$K35+$J36)) | L36: =IF($A36>NYears*12,"",IF(MOD($D36,3)=0,SUM($J34:$J36),0)) | M36: =IF($A36>NYears*12,"",IF(TaxFreq="Quarterly",$K36*12/$D36,$K36)) | N36: =IF($A36>NYears*12,"",LOOKUP($M36,TaxLower,TaxRate)) | O36: =IF($A36>NYears*12,"",IF(TaxFreq="Quarterly",IF(MOD($D36,3)=0,$L36*$N36,0),IF($D36=12,$K36*$N36,0))) | P36: =IF($A36>NYears*12,"",IF($D36=1,$O36,$P35+$O36)) | Q36: =IF($A36>NYears*12,"",IF($D36=12,MIN(WdrPct*IF(WdrBase="Post-tax profit",$K36-$P36,$K36),WdrCap),0)) | R36: =IF($A36>NYears*12,"",$F36+$J36-$O36-$Q36) | S36: =IF($A36>NYears*12,"",INT($R36/$E36))
A37: =33 | B37: =IF($A37>NYears*12,"",EDATE(StartMonth,$A37-1)) | C37: =IF($A37>NYears*12,"",INT(($A37-1)/12)+1) | D37: =IF($A37>NYears*12,"",MOD($A37-1,12)+1) | E37: =IF($A37>NYears*12,"",LotValue0*(1+LotGrowth)^($C37-1)) | F37: =IF($A37>NYears*12,"",IF($A37=1,InitInvest,$R36)) | G37: =IF($A37>NYears*12,"",INT($F37/$E37)) | H37: =IF($A37>NYears*12,"",$G37*$E37) | I37: =IF($A37>NYears*12,"",$F37-$H37) | J37: =IF($A37>NYears*12,"",$H37*RateA) | K37: =IF($A37>NYears*12,"",IF($D37=1,$J37,$K36+$J37)) | L37: =IF($A37>NYears*12,"",IF(MOD($D37,3)=0,SUM($J35:$J37),0)) | M37: =IF($A37>NYears*12,"",IF(TaxFreq="Quarterly",$K37*12/$D37,$K37)) | N37: =IF($A37>NYears*12,"",LOOKUP($M37,TaxLower,TaxRate)) | O37: =IF($A37>NYears*12,"",IF(TaxFreq="Quarterly",IF(MOD($D37,3)=0,$L37*$N37,0),IF($D37=12,$K37*$N37,0))) | P37: =IF($A37>NYears*12,"",IF($D37=1,$O37,$P36+$O37)) | Q37: =IF($A37>NYears*12,"",IF($D37=12,MIN(WdrPct*IF(WdrBase="Post-tax profit",$K37-$P37,$K37),WdrCap),0)) | R37: =IF($A37>NYears*12,"",$F37+$J37-$O37-$Q37) | S37: =IF($A37>NYears*12,"",INT($R37/$E37))
A38: =34 | B38: =IF($A38>NYears*12,"",EDATE(StartMonth,$A38-1)) | C38: =IF($A38>NYears*12,"",INT(($A38-1)/12)+1) | D38: =IF($A38>NYears*12,"",MOD($A38-1,12)+1) | E38: =IF($A38>NYears*12,"",LotValue0*(1+LotGrowth)^($C38-1)) | F38: =IF($A38>NYears*12,"",IF($A38=1,InitInvest,$R37)) | G38: =IF($A38>NYears*12,"",INT($F38/$E38)) | H38: =IF($A38>NYears*12,"",$G38*$E38) | I38: =IF($A38>NYears*12,"",$F38-$H38) | J38: =IF($A38>NYears*12,"",$H38*RateA) | K38: =IF($A38>NYears*12,"",IF($D38=1,$J38,$K37+$J38)) | L38: =IF($A38>NYears*12,"",IF(MOD($D38,3)=0,SUM($J36:$J38),0)) | M38: =IF($A38>NYears*12,"",IF(TaxFreq="Quarterly",$K38*12/$D38,$K38)) | N38: =IF($A38>NYears*12,"",LOOKUP($M38,TaxLower,TaxRate)) | O38: =IF($A38>NYears*12,"",IF(TaxFreq="Quarterly",IF(MOD($D38,3)=0,$L38*$N38,0),IF($D38=12,$K38*$N38,0))) | P38: =IF($A38>NYears*12,"",IF($D38=1,$O38,$P37+$O38)) | Q38: =IF($A38>NYears*12,"",IF($D38=12,MIN(WdrPct*IF(WdrBase="Post-tax profit",$K38-$P38,$K38),WdrCap),0)) | R38: =IF($A38>NYears*12,"",$F38+$J38-$O38-$Q38) | S38: =IF($A38>NYears*12,"",INT($R38/$E38))
A39: =35 | B39: =IF($A39>NYears*12,"",EDATE(StartMonth,$A39-1)) | C39: =IF($A39>NYears*12,"",INT(($A39-1)/12)+1) | D39: =IF($A39>NYears*12,"",MOD($A39-1,12)+1) | E39: =IF($A39>NYears*12,"",LotValue0*(1+LotGrowth)^($C39-1)) | F39: =IF($A39>NYears*12,"",IF($A39=1,InitInvest,$R38)) | G39: =IF($A39>NYears*12,"",INT($F39/$E39)) | H39: =IF($A39>NYears*12,"",$G39*$E39) | I39: =IF($A39>NYears*12,"",$F39-$H39) | J39: =IF($A39>NYears*12,"",$H39*RateA) | K39: =IF($A39>NYears*12,"",IF($D39=1,$J39,$K38+$J39)) | L39: =IF($A39>NYears*12,"",IF(MOD($D39,3)=0,SUM($J37:$J39),0)) | M39: =IF($A39>NYears*12,"",IF(TaxFreq="Quarterly",$K39*12/$D39,$K39)) | N39: =IF($A39>NYears*12,"",LOOKUP($M39,TaxLower,TaxRate)) | O39: =IF($A39>NYears*12,"",IF(TaxFreq="Quarterly",IF(MOD($D39,3)=0,$L39*$N39,0),IF($D39=12,$K39*$N39,0))) | P39: =IF($A39>NYears*12,"",IF($D39=1,$O39,$P38+$O39)) | Q39: =IF($A39>NYears*12,"",IF($D39=12,MIN(WdrPct*IF(WdrBase="Post-tax profit",$K39-$P39,$K39),WdrCap),0)) | R39: =IF($A39>NYears*12,"",$F39+$J39-$O39-$Q39) | S39: =IF($A39>NYears*12,"",INT($R39/$E39))
